import { Injectable, Logger, HttpException, HttpStatus } from '@nestjs/common';
import { PreparationAnalysisResponseDto } from './dto/preparation-analysis-response.dto';

@Injectable()
export class PreparationService {
    private readonly logger = new Logger(PreparationService.name);

    async analyze(
        cvFileBuffer: Buffer,
        cvFileName: string,
        feedbackText: string,
        requirementsLink: string,
    ): Promise<PreparationAnalysisResponseDto> {
        this.logger.log(`Получен новый запрос на оценку кандидата: ${cvFileName}`);

        try {
            //
            // !!! ЗДЕСЬ БУДЕТ ЛОГИКА ИЗ ТВОЕГО `analysis_service.analyze_preparation` !!!
            // Например, вызов AI, работа с Google Drive и т.д.
            //
            // Пока что мы вернем мок-ответ, как делали раньше.
            const mockResult: PreparationAnalysisResponseDto = {
                message: 'Analysis successful. Mocked data.',
                success: true,
                report: {
                    matching_table: [],
                    candidate_profile: '',
                    conclusion:
                },
            };

            this.logger.log('Анализ успешно завершен. Возвращается результат.');
            return mockResult;

        } catch (error) {
            this.logger.error(`Произошла ошибка во время анализа: ${error.message}`, error.stack);

            // Здесь мы можем обрабатывать специфичные ошибки, как ты делал с ValueError
            if (error instanceof Error /* Заменить на твой тип ошибки */) {
                throw new HttpException(error.message, HttpStatus.BAD_REQUEST);
            }

            // Общая ошибка "на всякий случай"
            throw new HttpException(
                'Произошла внутренняя ошибка сервера',
                HttpStatus.INTERNAL_SERVER_ERROR,
            );
        }
    }
}
